Workbook

Sheet IMPLEMENTASI MRP
C2: MATERIAL REQUIREMENTS PLANNING (METODE LFL, LEAD TIME 1 MINGGU, DEFECT RATE 2.5%
B6: MASTER PRODUCTION SCHEDULE (MPS) | D6: PD | E6: Minggu 1 | F6: Minggu 2 | G6: Minggu 3 | H6: Minggu 4 | I6: Minggu 5 | J6: Minggu 6 | K6: Minggu 7 | L6: Satuan | M6: Keterangan
B7: Demand / Pesanan (pcs) | D7: 100 | E7: 100 | F7: 100 | G7: 100 | H7: 100 | I7: 100 | J7: 100 | K7: 100 | L7: pcs | M7: Data permintaan / pesanan produksi
B8: MPS / Produksi (pcs) | D8: =D7 -> 100 | E8: =E7 -> 100 | F8: =F7 -> 100 | G8: =G7 -> 100 | H8: =H7 -> 100 | I8: =I7 -> 100 | J8: =J7 -> 100 | K8: =K7 -> 100 | L8: pcs | M8: Rencana produksi = memenuhi demand
B10: Komponen MRP LT: 1 minggu | D10: Minggu 0 | E10: Minggu 1 | F10: Minggu 2 | G10: Minggu 3 | H10: Minggu 4 | I10: Minggu 5 | J10: Minggu 6 | K10: Minggu 7 | L10: Satuan | M10: Keterangan / Rumus
B11: GR | C11: Gross Requirement (Kebutuhan Kotor) | E11: =E8*0.5 -> 50 | F11: =F8*0.5 -> 50 | G11: =G8*0.5 -> 50 | H11: =H8*0.5 -> 50 | I11: =I8*0.5 -> 50 | J11: =J8*0.5 -> 50 | K11: =K8*0.5 -> 50 | L11: kg | M11: GR = MPS × BOM = Produksi × 0,5 kg/pcs
B12: SR | C12: Scheduled Receipts (Penerimaan Terjadwal) | E12: 10 | F12: 0 | G12: 0 | H12: 0 | I12: 0 | J12: 0 | K12: 0 | L12: kg | M12: SR =Bahan baku yang sudah di pesan/dijadwalkan tiba
B13: PoH | C13: Projected On Hand (Persediaan Awal Periode) | D13: 20 | E13: =D13+E12+E15-E11 -> 0 | F13: =E13+F12+F15-F11 -> 0 | G13: =F13+G12+G15-G11 -> 0 | H13: =G13+H12+H15-H11 -> 0 | I13: =H13+I12+I15-I11 -> 0 | J13: =I13+J12+J15-J11 -> 0 | K13: =J13+K12+K15-K11 -> 0 | L13: kg | M13: PoH minggu ini = sisa stok minggu/periode kemarin
B14: NR | C14: Net Requirement (Kebutuhan Bersih) | E14: =MAX(0,E11-(D13+E12)) -> 20 | F14: =MAX(0,F11-(E13+F12)) -> 50 | G14: =MAX(0,G11-(F13+G12)) -> 50 | H14: =MAX(0,H11-(G13+H12)) -> 50 | I14: =MAX(0,I11-(H13+I12)) -> 50 | J14: =MAX(0,J11-(I13+J12)) -> 50 | K14: =MAX(0,K11-(J13+K12)) -> 50 | L14: kg | M14: NR = GR - PoH − SR + SS, dengan syarat min 0
B15: PORt | C15: Planned Order Receipt (Penerimaan Terencana) | E15: =D16 -> 20 | F15: =E16 -> 50 | G15: =F16 -> 50 | H15: =G16 -> 50 | I15: =H16 -> 50 | J15: =I16 -> 50 | K15: =J16 -> 50 | L15: kg | M15: PORt M(t) = Jumlah barang yang masuk yang sudah direncanakan dengan LT = 1 minggu
B16: PORel | C16: Planned Order Release (Pelepasan Pesanan Terencana) | D16: =E14 -> 20 | E16: =F14 -> 50 | F16: =G14 -> 50 | G16: =H14 -> 50 | H16: =I14 -> 50 | I16: =J14 -> 50 | J16: =K14 -> 50 | K16: 0 | L16: kg | M16: PORel = NR (Lot-for-Lot); Pesanan yang dikirim ke supplier

Sheet IMPLEMENTASI PEMESANAN BARANG
D2: IMPLEMENTASI PEMESANAN BARANG DENGAN STANDAR AQL 2,5% DALAM PO & QUALITY SPECIFICATION SHEET
D5: TAHAP 1: MENGIRIM TABEL RENCANA SAMPEL AQL 2,5
C8: Ukuran Lot (unit) | D8: Kode Huruf | E8: Ukuran Sampel (n) | F8: Acceptance Number (Ac ≤) | G8: Rejection Number (Re >)
C9: 2 – 8 | D9: A | E9: 2 | F9: 0 | G9: 1 | I9: Acceptance Number (Ac ≤)
C10: 9 – 15 | D10: B | E10: 3 | F10: 0 | G10: 1 | I10: Rejection Number (Re >)
C11: 16 – 25 | D11: C | E11: 5 | F11: 0 | G11: 1
C12: 26 – 50 | D12: D | E12: 8 | F12: 0 | G12: 1
C13: 51 – 90 | D13: E | E13: 13 | F13: 1 | G13: 2
C14: 91 – 150 | D14: F | E14: 20 | F14: 1 | G14: 2
C15: 151 – 280 | D15: G | E15: 32 | F15: 2 | G15: 3
C16: 281 – 500 | D16: H | E16: 50 | F16: 3 | G16: 4
C17: 501 – 1.200 | D17: J | E17: 80 | F17: 5 | G17: 6
C18: 1.201 – 3.200 | D18: K | E18: 125 | F18: 7 | G18: 8 | I18: Mengirim Tabel Rencana Sampel AQL 2.5, Klasifikasi tingkat defect, Standart Quality Control yang dipesan, Quality Specification Sheet bahan baku
C19: 3.201 – 10.000 | D19: L | E19: 200 | F19: 10 | G19: 11
C23: TAHAP 2: KLASIFIKASI TINGKAT DEFECT BAHAN BAKU KAIN BRAND.ID
C26: Kategori | D26: Contoh pada Kain | E26: Keterangan | F26: Perlakuan
C27: KRITIS | D27: Lubang besar, kain robek, salah jenis bahan | E27: Menggagalkan fungsi atau membahayakan produk | F27: Tidak ditoleransi (Ac = 0 khusus, tolak langsung)
C28: MAYOR | D28: Belang warna, lubang kecil, gramasi di luar toleransi | E28: Menurunkan mutu secara signifikan | F28: Ikuti Ac/Re AQL 2,5% (Tabel Tahap 1)
C29: MINOR | D29: Noda kecil yang dapat dihilangkan, kerutan ringan | E29: Cacat estetis kecil, tidak ganggu fungsi | F29: Ac/Re lebih longgar (AQL 4,0%)
C33: TAHAP 3: PENERAPAN STANDAR INSPEKSI AQL 2,5% PADA PENERIMAAN MATERIAL
C36: Parameter | D36: Nilai | E36: Nilai
C37: Ukuran Lot | D37: 15 unit | E37: Hasil PO (15 kg × 1 gulungan/kg)
C38: Tingkat Inspeksi | D38: Umum II | E38: Default SNI ISO 2859-1:2014
C39: Modus Inspeksi | D39: Normal | E39: Default sebelum aturan peralihan
C40: Tingkat AQL | D40: 2,5% | E40: Disepakati untuk Brand.id
C41: Kode Huruf Sampel | D41: B | E41: Lot 9–15 unit → Kode B
C42: Ukuran Sampel (n) | D42: 3 unit | E42: Tabel SNI, Kode B
C43: Acceptance Number (Ac) | D43: 0 | E43: Kode B, AQL 2,5% → Terima jika d ≤ 0
C44: Rejection Number (Re) | D44: 1 | E44: Kode B, AQL 2,5% → Tolak jika d ≥ 1
D48: TAHAP 4: PENYUSUNAN QUALITY SPECIFICATION SHEET (QSS) MATERIAL
C51: Atribut Material | D51: Spesifikasi | E51: Toleransi Min | F51: Toleransi Maks | G51: Perlakuan jika Tidak Sesuai
C52: Jenis Kain | D52: Cotton combed 30s | E52: - | F52: - | G52: Tidak ada penggantian jenis — tolak langsung
C53: Lebar Kain | D53: 180 cm | E53: 178 cm | F53: 182 cm | G53: Di luar ±2 cm → cacat Mayor → ikuti Ac/Re
C54: Gramasi | D54: 180 gsm | E54: 171 gsm | F54: 189 gsm | G54: Di luar ±5% → cacat Mayor → ikuti Ac/Re
C55: Warna / Pantone | D55: Putih solid (Pantone 11-0601) | E55: — | F55: — | G55: Beda shade antar gulungan = Mayor defect
C56: Panjang/Gulungan | D56: ≥ 5 meter | E56: 4,8 m | F56: — | G56: Kurang dari 4,8 m → Minors, negosiasi ulang
C57: Kemasan | D57: Gulungan, terbungkus plastik | E57: — | F57: — | G57: Basah/rusak = Kritis → tolak langsung
I60: Purchase Order dengan Quality Specification Sheet
D62: TAHAP 5: TEMPLATE PURCHASE ORDER & QUALITY SPECIFICATION SHEET
C65: PURCHASE ORDER DAN QUALITY SPECIFICATION SHEET
...

Sheet IMPLEMENTASI QUALITY CONTROL
F1: QUALITY CONTROL DENGAN SNI AQL 2.5% DAN CHECKLIST 5 POINT INSPEKSI
B4: No. | C4: Tanggal Masuk | D4: Kode Material | E4: Vendor | F4: Deskripsi Defect | G4: Ukuran Sampel (n) | H4: Kode Sampel | I4: Ac ≤ | J4: Re > | K4: Cacat Ditemukan | L4: Foto Bukti? | M4: Hasil AQL 2.5 | N4: Keputusan (LOLOS/RETUR/HOLD) | O4: Validasi Supervisor | P4: Koordinasi Vendor | Q4: Hasil Akhir | R4: Jadwal Pengiriman PO | S4: Tanggal Barang Sampai | T4: Status Pengiriman | U4: Keterangan
B5: 1 | C5: 1 Juni 2026 | D5: K-1-PUTIH | E5: Vendor A | F5: Warna tidak sesuai | G5: 8 | H5: F | I5: =IF(H5="","",IFERROR(VLOOKUP(H5,$AD$6:$AF$17,2,0),"?")) -> 1 | J5: =IF(H5="","",IFERROR(VLOOKUP(H5,$AD$6:$AF$17,3,0),"?")) -> 2 | K5: 1 | L5: Terlampir | M5: =IF(K5="","",IF(K5<=I5,"LOLOS",IF(K5>=J5,"RETUR","HOLD"))) -> LOLOS | N5: HOLD | O5: - | P5: - | Q5: RETURN | R5: 1 Mei 2026 | S5: =C5 -> 1 Juni 2026 | T5: =IF(S5="","",IF(S5<=R5,"TEPAT WAKTU","DELAY")) -> TEPAT WAKTU
B6: =1+B5 -> 2 | C6: 10 Juni 2026 | D6: K-1-HITAM | E6: Vendor B | F6: Robek | G6: 13 | H6: E | I6: =IF(H6="","",IFERROR(VLOOKUP(H6,$AD$6:$AF$17,2,0),"?")) -> 1 | J6: =IF(H6="","",IFERROR(VLOOKUP(H6,$AD$6:$AF$17,3,0),"?")) -> 2 | K6: 0 | L6: Terlampir | M6: =IF(K6="","",IF(K6<=I6,"LOLOS",IF(K6>=J6,"RETUR","HOLD"))) -> LOLOS | N6: LOLOS | O6: - | P6: - | Q6: LOLOS | R6: 9 Juni 2026 | S6: =C6 -> 10 Juni 2026 | T6: =IF(S6="","",IF(S6<=R6,"TEPAT WAKTU","DELAY")) -> TEPAT WAKTU | Z6: Ukuran Lot (unit) | AA6: Ukuran Sampel | AB6: Kode Material | AC6: Vendor | AD6: Kode Sampel | AE6: Ac ≤ | AF6: Re > | AG6: Keputusan | AH6: Hasil Akhir
B7: =1+B6 -> 3 | C7: 15 Juni 2026 | D7: K-1-ABU-ABU | E7: Vendor C | F7: Warna tidak sesuai | G7: 20 | H7: F | I7: =IF(H7="","",IFERROR(VLOOKUP(H7,$AD$6:$AF$17,2,0),"?")) -> 1 | J7: =IF(H7="","",IFERROR(VLOOKUP(H7,$AD$6:$AF$17,3,0),"?")) -> 2 | K7: 2 | L7: Terlampir | M7: =IF(K7="","",IF(K7<=I7,"LOLOS",IF(K7>=J7,"RETUR","HOLD"))) -> RETUR | N7: RETURN | O7: - | P7: - | Q7: RETURN | R7: 14 Juni 2026 | S7: =C7 -> 15 Juni 2026 | T7: =IF(S7="","",IF(S7<=R7,"TEPAT WAKTU","DELAY")) -> DELAY | Z7: 2 – 8 | AA7: 2 | AB7: K-1-PUTIH | AC7: Vendor A | AD7: A | AE7: 0 | AF7: 1 | AG7: LOLOS | AH7: LOLOS
B8: =1+B7 -> 4 | C8: 16 Juni 2026 | D8: K-1-PUTIH | E8: Vendor A | G8: 2 | H8: A | I8: =IF(H8="","",IFERROR(VLOOKUP(H8,$AD$6:$AF$17,2,0),"?")) -> 0 | J8: =IF(H8="","",IFERROR(VLOOKUP(H8,$AD$6:$AF$17,3,0),"?")) -> 1 | K8: 2 | L8: Terlampir | M8: =IF(K8="","",IF(K8<=I8,"LOLOS",IF(K8>=J8,"RETUR","HOLD"))) -> RETUR | N8: RETURN | O8: - | P8: - | Q8: LOLOS | R8: 17 Juni 2026 | S8: =C8 -> 16 Juni 2026 | T8: =IF(S8="","",IF(S8<=R8,"TEPAT WAKTU","DELAY")) -> TEPAT WAKTU | Z8: 9 – 15 | AA8: 3 | AB8: K-1-HITAM | AC8: Vendor B | AD8: B | AE8: 0 | AF8: 1 | AG8: RETURN | AH8: RETURN
B9: =1+B8 -> 5 | C9: 17 Juni 2026 | D9: K-1-HITAM | E9: Vendor B | G9: 50 | H9: H | I9: =IF(H9="","",IFERROR(VLOOKUP(H9,$AD$6:$AF$17,2,0),"?")) -> 3 | J9: =IF(H9="","",IFERROR(VLOOKUP(H9,$AD$6:$AF$17,3,0),"?")) -> 4 | K9: 2 | L9: Terlampir | M9: =IF(K9="","",IF(K9<=I9,"LOLOS",IF(K9>=J9,"RETUR","HOLD"))) -> LOLOS | N9: HOLD | O9: - | P9: - | Q9: LOLOS | R9: 16 Juni 2026 | S9: =C9 -> 17 Juni 2026 | T9: =IF(S9="","",IF(S9<=R9,"TEPAT WAKTU","DELAY")) -> DELAY | Z9: 16 – 25 | AA9: 5 | AB9: K-1-ABU-ABU | AC9: Vendor C | AD9: C | AE9: 0 | AF9: 1 | AG9: HOLD
B10: =1+B9 -> 6 | C10: 18 Juni 2026 | D10: K-1-ABU-ABU | E10: Vendor C | G10: 3 | H10: B | I10: =IF(H10="","",IFERROR(VLOOKUP(H10,$AD$6:$AF$17,2,0),"?")) -> 0 | J10: =IF(H10="","",IFERROR(VLOOKUP(H10,$AD$6:$AF$17,3,0),"?")) -> 1 | K10: 20 | L10: Terlampir | M10: =IF(K10="","",IF(K10<=I10,"LOLOS",IF(K10>=J10,"RETUR","HOLD"))) -> RETUR | N10: LOLOS | O10: - | P10: - | Q10: RETURN | R10: 17 Juni 2026 | S10: =C10 -> 18 Juni 2026 | T10: =IF(S10="","",IF(S10<=R10,"TEPAT WAKTU","DELAY")) -> DELAY | Z10: 26 – 50 | AA10: 8 | AD10: D | AE10: 0 | AF10: 1
B11: =1+B10 -> 7 | I11: =IF(H11="","",IFERROR(VLOOKUP(H11,$AD$6:$AF$17,2,0),"?")) | J11: =IF(H11="","",IFERROR(VLOOKUP(H11,$AD$6:$AF$17,3,0),"?")) | M11: =IF(K11="","",IF(K11<=I11,"LOLOS",IF(K11>=J11,"RETUR","HOLD"))) | Z11: 51 – 90 | AA11: 13 | AD11: E | AE11: 1 | AF11: 2
B12: =1+B11 -> 8 | I12: =IF(H12="","",IFERROR(VLOOKUP(H12,$AD$6:$AF$17,2,0),"?")) | J12: =IF(H12="","",IFERROR(VLOOKUP(H12,$AD$6:$AF$17,3,0),"?")) | M12: =IF(K12="","",IF(K12<=I12,"LOLOS",IF(K12>=J12,"RETUR","HOLD"))) | Z12: 91 – 150 | AA12: 20 | AD12: F | AE12: 1 | AF12: 2
B13: =1+B12 -> 9 | I13: =IF(H13="","",IFERROR(VLOOKUP(H13,$AD$6:$AF$17,2,0),"?")) | J13: =IF(H13="","",IFERROR(VLOOKUP(H13,$AD$6:$AF$17,3,0),"?")) | M13: =IF(K13="","",IF(K13<=I13,"LOLOS",IF(K13>=J13,"RETUR","HOLD"))) | Z13: 151 – 280 | AA13: 32 | AD13: G | AE13: 2 | AF13: 3
B14: =1+B13 -> 10 | I14: =IF(H14="","",IFERROR(VLOOKUP(H14,$AD$6:$AF$17,2,0),"?")) | J14: =IF(H14="","",IFERROR(VLOOKUP(H14,$AD$6:$AF$17,3,0),"?")) | M14: =IF(K14="","",IF(K14<=I14,"LOLOS",IF(K14>=J14,"RETUR","HOLD"))) | Z14: 281 – 500 | AA14: 50 | AD14: H | AE14: 3 | AF14: 4
B15: =1+B14 -> 11 | I15: =IF(H15="","",IFERROR(VLOOKUP(H15,$AD$6:$AF$17,2,0),"?")) | J15: =IF(H15="","",IFERROR(VLOOKUP(H15,$AD$6:$AF$17,3,0),"?")) | M15: =IF(K15="","",IF(K15<=I15,"LOLOS",IF(K15>=J15,"RETUR","HOLD"))) | Z15: 501 – 1.200 | AA15: 80 | AD15: J | AE15: 5 | AF15: 6
B16: =1+B15 -> 12 | I16: =IF(H16="","",IFERROR(VLOOKUP(H16,$AD$6:$AF$17,2,0),"?")) | J16: =IF(H16="","",IFERROR(VLOOKUP(H16,$AD$6:$AF$17,3,0),"?")) | M16: =IF(K16="","",IF(K16<=I16,"LOLOS",IF(K16>=J16,"RETUR","HOLD"))) | Z16: 1.201 – 3.200 | AA16: 125 | AD16: K | AE16: 7 | AF16: 8
B17: =1+B16 -> 13 | I17: =IF(H17="","",IFERROR(VLOOKUP(H17,$AD$6:$AF$17,2,0),"?")) | J17: =IF(H17="","",IFERROR(VLOOKUP(H17,$AD$6:$AF$17,3,0),"?")) | M17: =IF(K17="","",IF(K17<=I17,"LOLOS",IF(K17>=J17,"RETUR","HOLD"))) | Z17: 3.201 – 10.000 | AA17: 200 | AD17: L | AE17: 10 | AF17: 11
B18: =1+B17 -> 14 | I18: =IF(H18="","",IFERROR(VLOOKUP(H18,$AD$6:$AF$17,2,0),"?")) | J18: =IF(H18="","",IFERROR(VLOOKUP(H18,$AD$6:$AF$17,3,0),"?")) | M18: =IF(K18="","",IF(K18<=I18,"LOLOS",IF(K18>=J18,"RETUR","HOLD")))
B19: =1+B18 -> 15 | I19: =IF(H19="","",IFERROR(VLOOKUP(H19,$AD$6:$AF$17,2,0),"?")) | J19: =IF(H19="","",IFERROR(VLOOKUP(H19,$AD$6:$AF$17,3,0),"?")) | M19: =IF(K19="","",IF(K19<=I19,"LOLOS",IF(K19>=J19,"RETUR","HOLD")))
B20: =1+B19 -> 16 | I20: =IF(H20="","",IFERROR(VLOOKUP(H20,$AD$6:$AF$17,2,0),"?")) | J20: =IF(H20="","",IFERROR(VLOOKUP(H20,$AD$6:$AF$17,3,0),"?")) | M20: =IF(K20="","",IF(K20<=I20,"LOLOS",IF(K20>=J20,"RETUR","HOLD")))
B21: =1+B20 -> 17 | I21: =IF(H21="","",IFERROR(VLOOKUP(H21,$AD$6:$AF$17,2,0),"?")) | J21: =IF(H21="","",IFERROR(VLOOKUP(H21,$AD$6:$AF$17,3,0),"?")) | M21: =IF(K21="","",IF(K21<=I21,"LOLOS",IF(K21>=J21,"RETUR","HOLD")))
B22: =1+B21 -> 18 | I22: =IF(H22="","",IFERROR(VLOOKUP(H22,$AD$6:$AF$17,2,0),"?")) | J22: =IF(H22="","",IFERROR(VLOOKUP(H22,$AD$6:$AF$17,3,0),"?")) | M22: =IF(K22="","",IF(K22<=I22,"LOLOS",IF(K22>=J22,"RETUR","HOLD")))
B23: =1+B22 -> 19 | I23: =IF(H23="","",IFERROR(VLOOKUP(H23,$AD$6:$AF$17,2,0),"?")) | J23: =IF(H23="","",IFERROR(VLOOKUP(H23,$AD$6:$AF$17,3,0),"?")) | M23: =IF(K23="","",IF(K23<=I23,"LOLOS",IF(K23>=J23,"RETUR","HOLD")))
B24: =1+B23 -> 20 | I24: =IF(H24="","",IFERROR(VLOOKUP(H24,$AD$6:$AF$17,2,0),"?")) | J24: =IF(H24="","",IFERROR(VLOOKUP(H24,$AD$6:$AF$17,3,0),"?")) | M24: =IF(K24="","",IF(K24<=I24,"LOLOS",IF(K24>=J24,"RETUR","HOLD")))
B25: =1+B24 -> 21 | I25: =IF(H25="","",IFERROR(VLOOKUP(H25,$AD$6:$AF$17,2,0),"?")) | J25: =IF(H25="","",IFERROR(VLOOKUP(H25,$AD$6:$AF$17,3,0),"?")) | M25: =IF(K25="","",IF(K25<=I25,"LOLOS",IF(K25>=J25,"RETUR","HOLD")))
B26: =1+B25 -> 22 | I26: =IF(H26="","",IFERROR(VLOOKUP(H26,$AD$6:$AF$17,2,0),"?")) | J26: =IF(H26="","",IFERROR(VLOOKUP(H26,$AD$6:$AF$17,3,0),"?")) | M26: =IF(K26="","",IF(K26<=I26,"LOLOS",IF(K26>=J26,"RETUR","HOLD")))
B27: =1+B26 -> 23 | I27: =IF(H27="","",IFERROR(VLOOKUP(H27,$AD$6:$AF$17,2,0),"?")) | J27: =IF(H27="","",IFERROR(VLOOKUP(H27,$AD$6:$AF$17,3,0),"?")) | M27: =IF(K27="","",IF(K27<=I27,"LOLOS",IF(K27>=J27,"RETUR","HOLD")))
B28: =1+B27 -> 24 | I28: =IF(H28="","",IFERROR(VLOOKUP(H28,$AD$6:$AF$17,2,0),"?")) | J28: =IF(H28="","",IFERROR(VLOOKUP(H28,$AD$6:$AF$17,3,0),"?")) | M28: =IF(K28="","",IF(K28<=I28,"LOLOS",IF(K28>=J28,"RETUR","HOLD")))
B29: =1+B28 -> 25 | I29: =IF(H29="","",IFERROR(VLOOKUP(H29,$AD$6:$AF$17,2,0),"?")) | J29: =IF(H29="","",IFERROR(VLOOKUP(H29,$AD$6:$AF$17,3,0),"?")) | M29: =IF(K29="","",IF(K29<=I29,"LOLOS",IF(K29>=J29,"RETUR","HOLD")))

Sheet IMPLEMENTASI FIFO
D2: PENYIMPANAN METODE FIFO DENGAN BATAS KAPASITAS 500 KG
B5: Tanggal | C5: Jenis (IN/OUT) | D5: Kode Material | E5: Vendor | F5: Masuk (kg) | G5: Keluar (kg) | H5: Total Gudang (kg) | I5: Margin Kapasitas (kg)
B6: 1 Juni 2026 | C6: IN | D6: K-1-PUTIH | E6: Vendor A | F6: 100 | H6: =F6-G6 -> 100 | I6: =500-H6 -> 400
B7: 2 Juni 2026 | C7: IN | D7: K-1-HITAM | E7: Vendor B | F7: 90 | H7: =H6+F7-G7 -> 190 | I7: =500-H7 -> 310 | K7: Kode Material | L7: Total Masuk (kg) | M7: Total Keluar (kg) | N7: Sisa Stok (kg) | O7: Status
B8: 3 Juni 2026 | C8: IN | D8: K-1-ABU-ABU | E8: Vendor C | F8: 98 | H8: =H7+F8-G8 -> 288 | I8: =500-H8 -> 212 | K8: K-1-PUTIH | L8: =SUMIFS($F:$F,$D:$D,$K8,$C:$C,"IN") -> 200 | M8: =SUMIFS($G:$G,$D:$D,$K8,$C:$C,"OUT") -> 143 | N8: =L8-M8 -> 57 | O8: =IF(N8>=100,"OVER LOAD",IF(N8>=50,"AMAN","PESAN ULANG")) -> AMAN
B9: 4 Juni 2026 | C9: IN | D9: K-1-PUTIH | E9: Vendor A | F9: 100 | H9: =H8+F9-G9 -> 388 | I9: =500-H9 -> 112 | K9: K-1-HITAM | L9: =SUMIFS($F:$F,$D:$D,$K9,$C:$C,"IN") -> 90 | M9: =SUMIFS($G:$G,$D:$D,$K9,$C:$C,"OUT") -> 0 | N9: =L9-M9 -> 90 | O9: =IF(N9>=100,"OVER LOAD",IF(N9>=50,"AMAN","PESAN ULANG")) -> AMAN
B10: 5 Juni 2026 | C10: OUT | D10: K-1-PUTIH | E10: Vendor B | G10: 98 | H10: =H9+F10-G10 -> 290 | I10: =500-H10 -> 210 | K10: K-1-ABU-ABU | L10: =SUMIFS($F:$F,$D:$D,$K10,$C:$C,"IN") -> 98 | M10: =SUMIFS($G:$G,$D:$D,$K10,$C:$C,"OUT") -> 0 | N10: =L10-M10 -> 98 | O10: =IF(N10>=100,"OVER LOAD",IF(N10>=50,"AMAN","PESAN ULANG")) -> AMAN
B11: 10 Juni 2026 | C11: OUT | D11: K-1-PUTIH | E11: Vendor B | G11: 45 | H11: =H10+F11-G11 -> 245 | I11: =500-H11 -> 255
K20: Jenis (IN/OUT) | L20: Kode Material | M20: Vendor
K21: IN | L21: K-1-PUTIH | M21: Vendor A
K22: OUT | L22: K-1-HITAM | M22: Vendor B
L23: K-1-ABU-ABU | M23: Vendor C

Sheet ADMINISTRASI DEFECT
C3: DATA TOTAL PEMESANAN DAN TOTAL JUMLAH BARANG CACAT | K3: DATA TOTAL PENGIRIMAN DELAY & TEPAT WAKTU
B6: Vendor | C6: Kode Material | D6: Total Pemasanan | E6: Ukuran Sampel (n) | F6: Total Cacat Ditemukan | G6: Total Hasil Akhir Lolos | H6: Total Hasil Akhir Return | K6: Vendor | L6: Total Pengiriman | M6: Total Pengiriman Delay | N6: Total Pengiriman Tepat Waktu
B7: Vendor A | C7: K-1-PUTIH | D7: =COUNTIF('IMPLEMENTASI QUALITY CONTROL'!$E$5:$E$29,"Vendor A") -> 2 | E7: =SUMIF('IMPLEMENTASI QUALITY CONTROL'!$E$5:$E$29,B7,'IMPLEMENTASI QUALITY CONTROL'!$G$5:$G$29) -> 10 | F7: =SUMIF('IMPLEMENTASI QUALITY CONTROL'!$E$5:$E$29,B7,'IMPLEMENTASI QUALITY CONTROL'!$K$5:$K$29) -> 3 | G7: =COUNTIFS('IMPLEMENTASI QUALITY CONTROL'!$E$5:$E$29,B7,'IMPLEMENTASI QUALITY CONTROL'!$Q$5:$Q$29,"LOLOS") -> 1 | H7: =COUNTIFS('IMPLEMENTASI QUALITY CONTROL'!$E$5:$E$29,B7,'IMPLEMENTASI QUALITY CONTROL'!$Q$5:$Q$29,"RETURN") -> 1 | K7: Vendor A | L7: =COUNTIF('IMPLEMENTASI QUALITY CONTROL'!E5:E29,"Vendor A") -> 2 | M7: =COUNTIFS('IMPLEMENTASI QUALITY CONTROL'!E5:E29,"Vendor A",'IMPLEMENTASI QUALITY CONTROL'!T5:T29,"DELAY") -> 0 | N7: =COUNTIFS('IMPLEMENTASI QUALITY CONTROL'!E5:E29,"Vendor A",'IMPLEMENTASI QUALITY CONTROL'!T5:T29,"TEPAT WAKTU") -> 2
B8: Vendor B | C8: K-1-HITAM | D8: =COUNTIF('IMPLEMENTASI QUALITY CONTROL'!$E$5:$E$29,"Vendor B") -> 2 | E8: =SUMIF('IMPLEMENTASI QUALITY CONTROL'!$E$5:$E$29,B8,'IMPLEMENTASI QUALITY CONTROL'!$G$5:$G$29) -> 63 | F8: =SUMIF('IMPLEMENTASI QUALITY CONTROL'!$E$5:$E$29,B8,'IMPLEMENTASI QUALITY CONTROL'!$K$5:$K$29) -> 2 | G8: =COUNTIFS('IMPLEMENTASI QUALITY CONTROL'!$E$5:$E$29,B8,'IMPLEMENTASI QUALITY CONTROL'!$Q$5:$Q$29,"LOLOS") -> 2 | H8: =COUNTIFS('IMPLEMENTASI QUALITY CONTROL'!$E$5:$E$29,B8,'IMPLEMENTASI QUALITY CONTROL'!$Q$5:$Q$29,"RETURN") -> 0 | K8: Vendor B | L8: =COUNTIF('IMPLEMENTASI QUALITY CONTROL'!E5:E29,"Vendor B") -> 2 | M8: =COUNTIFS('IMPLEMENTASI QUALITY CONTROL'!E5:E29,"Vendor B",'IMPLEMENTASI QUALITY CONTROL'!T5:T29,"DELAY") -> 1 | N8: =COUNTIFS('IMPLEMENTASI QUALITY CONTROL'!E5:E29,"Vendor B",'IMPLEMENTASI QUALITY CONTROL'!T5:T29,"TEPAT WAKTU") -> 1
B9: Vendor C | C9: K-1-ABU-ABU | D9: =COUNTIF('IMPLEMENTASI QUALITY CONTROL'!$E$5:$E$29,"Vendor C") -> 2 | E9: =SUMIF('IMPLEMENTASI QUALITY CONTROL'!$E$5:$E$29,B9,'IMPLEMENTASI QUALITY CONTROL'!$G$5:$G$29) -> 23 | F9: =SUMIF('IMPLEMENTASI QUALITY CONTROL'!$E$5:$E$29,B9,'IMPLEMENTASI QUALITY CONTROL'!$K$5:$K$29) -> 22 | G9: =COUNTIFS('IMPLEMENTASI QUALITY CONTROL'!$E$5:$E$29,B9,'IMPLEMENTASI QUALITY CONTROL'!$Q$5:$Q$29,"LOLOS") -> 0 | H9: =COUNTIFS('IMPLEMENTASI QUALITY CONTROL'!$E$5:$E$29,B9,'IMPLEMENTASI QUALITY CONTROL'!$Q$5:$Q$29,"RETURN") -> 2 | K9: Vendor C | L9: =COUNTIF('IMPLEMENTASI QUALITY CONTROL'!E5:E29,"Vendor C") -> 2 | M9: =COUNTIFS('IMPLEMENTASI QUALITY CONTROL'!E5:E29,"Vendor C",'IMPLEMENTASI QUALITY CONTROL'!T5:T29,"DELAY") -> 2 | N9: =COUNTIFS('IMPLEMENTASI QUALITY CONTROL'!E5:E29,"Vendor C",'IMPLEMENTASI QUALITY CONTROL'!T5:T29,"TEPAT WAKTU") -> 0

Sheet IMPLEMENTASI VPI
E4: TABEL PERHITUNGAN KPI UMKM
D7: Vendor | E7: Qty Diterima (kg) | F7: Qty Defect (kg) | G7: Total Pengiriman | H7: Tepat Waktu | I7: Harga (Rp/kg)
D8: Vendor A | E8: ='ADMINISTRASI DEFECT'!D7 -> 2 | F8: ='ADMINISTRASI DEFECT'!H7 -> 1 | G8: ='ADMINISTRASI DEFECT'!L7 -> 2 | H8: ='ADMINISTRASI DEFECT'!N7 -> 2 | I8: 75
D9: Vendor B | E9: ='ADMINISTRASI DEFECT'!D8 -> 2 | F9: ='ADMINISTRASI DEFECT'!H8 -> 0 | G9: ='ADMINISTRASI DEFECT'!M8 -> 1 | H9: ='ADMINISTRASI DEFECT'!N8 -> 1 | I9: 73
D10: Vendor C | E10: ='ADMINISTRASI DEFECT'!D9 -> 2 | F10: ='ADMINISTRASI DEFECT'!H9 -> 2 | G10: ='ADMINISTRASI DEFECT'!M9 -> 2 | H10: ='ADMINISTRASI DEFECT'!N9 -> 0 | I10: 72
E19: TABEL SKORING VPI PER VENDOR | K19: PERSENTASI KPI UMKM
D22: Vendor | E22: Quality | F22: Delivery | G22: Price | H22: VPI | I22: Ranking | K22: =E22 -> Quality | L22: 0.5
D23: =D8 -> Vendor A | E23: =((E8-F8)/E8)*100 -> 50 | F23: =((H8/G8)*100) -> 100 | G23: =((I10/I8)*100) -> 96 | H23: =(E23*L22)+(F23*L23)+(G23*L24) -> 74.2 | I23: =RANK(H23,$H$23:$H$25,0) -> 2 | K23: =F22 -> Delivery | L23: 0.3
D24: =D9 -> Vendor B | E24: =((E9-F9)/E9)*100 -> 100 | F24: =((H9/G9)*100) -> 100 | G24: =((I10/I9)*100) -> 98.630137 | H24: =(E24*L22)+(F24*L23)+(G24*L24) -> 99.726027 | I24: =RANK(H24,$H$23:$H$25,0) -> 1 | K24: =G22 -> Price | L24: 0.2
D25: =D10 -> Vendor C | E25: =((E10-F10)/E10)*100 -> 0 | F25: =((H10/G10)*100) -> 0 | G25: =((I10/I10)*100) -> 100 | H25: =(E25*L22)+(F25*L23)+(G25*L24) -> 20 | I25: =RANK(H25,$H$23:$H$25,0) -> 3

Sheet Dasbord
K5: VISUALISASI DASBOARD
H17: VENDOR TERBAIK | Q17: SISA STOK GUDANG
BO18: PERFORMA PENGIRIMAN PER VENDOR
H19: =INDEX(BP40:BP42,MATCH(MAX(BT40:BT42),BT40:BT42,0)) -> Vendor B | Q19: =BP30 -> K-1-PUTIH | S19: =BP31 -> K-1-HITAM | U19: =BP32 -> K-1-ABU-ABU | BO19: Vendor | BQ19: Tepat Waktu | BR19: Total Pengiriman
Q20: =BQ30 -> 57 | S20: =BQ31 -> 90 | U20: =BQ32 -> 98 | BO20: Vendor A | BQ20: ='ADMINISTRASI DEFECT'!N7 -> 2 | BR20: ='ADMINISTRASI DEFECT'!L7 -> 2
BO21: Vendor B | BQ21: ='ADMINISTRASI DEFECT'!N8 -> 1 | BR21: ='ADMINISTRASI DEFECT'!L8 -> 2
BO22: Vendor C | BQ22: ='ADMINISTRASI DEFECT'!N9 -> 0 | BR22: ='ADMINISTRASI DEFECT'!L9 -> 2
BP28: STOK DI GUDANG
BP29: Kode Material | BQ29: Sisa Stok (kg) | BR29: Status
BP30: ='IMPLEMENTASI FIFO'!K8 -> K-1-PUTIH | BQ30: ='IMPLEMENTASI FIFO'!N8 -> 57 | BR30: ='IMPLEMENTASI FIFO'!O8 -> AMAN
BP31: ='IMPLEMENTASI FIFO'!K9 -> K-1-HITAM | BQ31: ='IMPLEMENTASI FIFO'!N9 -> 90 | BR31: ='IMPLEMENTASI FIFO'!O9 -> AMAN
BP32: ='IMPLEMENTASI FIFO'!K10 -> K-1-ABU-ABU | BQ32: ='IMPLEMENTASI FIFO'!N10 -> 98 | BR32: ='IMPLEMENTASI FIFO'!O10 -> AMAN
BP38: VENDOR PERFORMANCE INDEX (VPI) & RANKING
BP39: Vendor | BQ39: Quality | BR39: Delivery | BS39: Price | BT39: VPI | BU39: Ranking
BP40: ='IMPLEMENTASI VPI'!D23 -> Vendor A | BQ40: ='IMPLEMENTASI VPI'!E23 -> 50 | BR40: ='IMPLEMENTASI VPI'!F23 -> 100 | BS40: ='IMPLEMENTASI VPI'!G23 -> 96 | BT40: ='IMPLEMENTASI VPI'!H23 -> 74.2 | BU40: ='IMPLEMENTASI VPI'!I23 -> 2
BP41: ='IMPLEMENTASI VPI'!D24 -> Vendor B | BQ41: ='IMPLEMENTASI VPI'!E24 -> 100 | BR41: ='IMPLEMENTASI VPI'!F24 -> 100 | BS41: ='IMPLEMENTASI VPI'!G24 -> 98.630137 | BT41: ='IMPLEMENTASI VPI'!H24 -> 99.726027 | BU41: ='IMPLEMENTASI VPI'!I24 -> 1
BP42: ='IMPLEMENTASI VPI'!D25 -> Vendor C | BQ42: ='IMPLEMENTASI VPI'!E25 -> 0 | BR42: ='IMPLEMENTASI VPI'!F25 -> 0 | BS42: ='IMPLEMENTASI VPI'!G25 -> 100 | BT42: ='IMPLEMENTASI VPI'!H25 -> 20 | BU42: ='IMPLEMENTASI VPI'!I25 -> 3
BP48: JUMLAH PESANAN PER VENDOR
BP49: Vendor | BQ49: Total Pesanan | BR49: Lolos | BS49: Return
BP50: ='ADMINISTRASI DEFECT'!B7 -> Vendor A | BQ50: ='ADMINISTRASI DEFECT'!D7 -> 2 | BR50: ='ADMINISTRASI DEFECT'!G7 -> 1 | BS50: ='ADMINISTRASI DEFECT'!H7 -> 1
BP51: ='ADMINISTRASI DEFECT'!B8 -> Vendor B | BQ51: ='ADMINISTRASI DEFECT'!D8 -> 2 | BR51: ='ADMINISTRASI DEFECT'!G8 -> 2 | BS51: ='ADMINISTRASI DEFECT'!H8 -> 0
BP52: ='ADMINISTRASI DEFECT'!B9 -> Vendor C | BQ52: ='ADMINISTRASI DEFECT'!D9 -> 2 | BR52: ='ADMINISTRASI DEFECT'!G9 -> 0 | BS52: ='ADMINISTRASI DEFECT'!H9 -> 2
